Exception on /api/v1/com/20 [GET]
Traceback (most recent call last):
  File "P:\Programme\Anaconda\lib\site-packages\flask\app.py", line 2446, in wsgi_app
    response = self.full_dispatch_request()
  File "P:\Programme\Anaconda\lib\site-packages\flask\app.py", line 1951, in full_dispatch_request
    rv = self.handle_user_exception(e)
  File "P:\Programme\Anaconda\lib\site-packages\flask\app.py", line 1820, in handle_user_exception
    reraise(exc_type, exc_value, tb)
  File "P:\Programme\Anaconda\lib\site-packages\flask\_compat.py", line 39, in reraise
    raise value
  File "P:\Programme\Anaconda\lib\site-packages\flask\app.py", line 1949, in full_dispatch_request
    rv = self.dispatch_request()
  File "P:\Programme\Anaconda\lib\site-packages\flask\app.py", line 1935, in dispatch_request
    return self.view_functions[rule.endpoint](**req.view_args)
  File "D:\Git\Private\RaspberryPi\RaspberryProjects\com\com\ControllerClass\API\com.py", line 17, in api_all
    return controller.calculate(name)
TypeError: calculate() takes 1 positional argument but 2 were given
Exception on /api/v1/com/20 [GET]
Traceback (most recent call last):
  File "P:\Programme\Anaconda\lib\site-packages\flask\app.py", line 2446, in wsgi_app
    response = self.full_dispatch_request()
  File "P:\Programme\Anaconda\lib\site-packages\flask\app.py", line 1951, in full_dispatch_request
    rv = self.handle_user_exception(e)
  File "P:\Programme\Anaconda\lib\site-packages\flask\app.py", line 1820, in handle_user_exception
    reraise(exc_type, exc_value, tb)
  File "P:\Programme\Anaconda\lib\site-packages\flask\_compat.py", line 39, in reraise
    raise value
  File "P:\Programme\Anaconda\lib\site-packages\flask\app.py", line 1949, in full_dispatch_request
    rv = self.dispatch_request()
  File "P:\Programme\Anaconda\lib\site-packages\flask\app.py", line 1935, in dispatch_request
    return self.view_functions[rule.endpoint](**req.view_args)
  File "D:\Git\Private\RaspberryPi\RaspberryProjects\com\com\ControllerClass\API\com.py", line 17, in api_all
    return controller.calculate(name)
TypeError: calculate() takes 1 positional argument but 2 were given
Exception on /api/v1/com/20 [GET]
Traceback (most recent call last):
  File "P:\Programme\Anaconda\lib\site-packages\flask\app.py", line 2446, in wsgi_app
    response = self.full_dispatch_request()
  File "P:\Programme\Anaconda\lib\site-packages\flask\app.py", line 1951, in full_dispatch_request
    rv = self.handle_user_exception(e)
  File "P:\Programme\Anaconda\lib\site-packages\flask\app.py", line 1820, in handle_user_exception
    reraise(exc_type, exc_value, tb)
  File "P:\Programme\Anaconda\lib\site-packages\flask\_compat.py", line 39, in reraise
    raise value
  File "P:\Programme\Anaconda\lib\site-packages\flask\app.py", line 1949, in full_dispatch_request
    rv = self.dispatch_request()
  File "P:\Programme\Anaconda\lib\site-packages\flask\app.py", line 1935, in dispatch_request
    return self.view_functions[rule.endpoint](**req.view_args)
  File "D:\Git\Private\RaspberryPi\RaspberryProjects\com\com\ControllerClass\API\com.py", line 17, in api_all
    return controller.calculate(name)
TypeError: calculate() takes 1 positional argument but 2 were given
Exception on /api/v1/com/20 [GET]
Traceback (most recent call last):
  File "P:\Programme\Anaconda\lib\site-packages\flask\app.py", line 2446, in wsgi_app
    response = self.full_dispatch_request()
  File "P:\Programme\Anaconda\lib\site-packages\flask\app.py", line 1951, in full_dispatch_request
    rv = self.handle_user_exception(e)
  File "P:\Programme\Anaconda\lib\site-packages\flask\app.py", line 1820, in handle_user_exception
    reraise(exc_type, exc_value, tb)
  File "P:\Programme\Anaconda\lib\site-packages\flask\_compat.py", line 39, in reraise
    raise value
  File "P:\Programme\Anaconda\lib\site-packages\flask\app.py", line 1949, in full_dispatch_request
    rv = self.dispatch_request()
  File "P:\Programme\Anaconda\lib\site-packages\flask\app.py", line 1935, in dispatch_request
    return self.view_functions[rule.endpoint](**req.view_args)
TypeError: api_all() got an unexpected keyword argument 'id'
Exception on /api/v1/com/20 [GET]
Traceback (most recent call last):
  File "P:\Programme\Anaconda\lib\site-packages\flask\app.py", line 2446, in wsgi_app
    response = self.full_dispatch_request()
  File "P:\Programme\Anaconda\lib\site-packages\flask\app.py", line 1951, in full_dispatch_request
    rv = self.handle_user_exception(e)
  File "P:\Programme\Anaconda\lib\site-packages\flask\app.py", line 1820, in handle_user_exception
    reraise(exc_type, exc_value, tb)
  File "P:\Programme\Anaconda\lib\site-packages\flask\_compat.py", line 39, in reraise
    raise value
  File "P:\Programme\Anaconda\lib\site-packages\flask\app.py", line 1949, in full_dispatch_request
    rv = self.dispatch_request()
  File "P:\Programme\Anaconda\lib\site-packages\flask\app.py", line 1935, in dispatch_request
    return self.view_functions[rule.endpoint](**req.view_args)
  File "D:\Git\Private\RaspberryPi\RaspberryProjects\com\com\ControllerClass\API\com.py", line 14, in api_all
    print ("Das ist die uebermittelte id " + id)
TypeError: can only concatenate str (not "int") to str
Exception on /api/v1/com/20 [GET]
Traceback (most recent call last):
  File "P:\Programme\Anaconda\lib\site-packages\flask\app.py", line 2446, in wsgi_app
    response = self.full_dispatch_request()
  File "P:\Programme\Anaconda\lib\site-packages\flask\app.py", line 1952, in full_dispatch_request
    return self.finalize_request(rv)
  File "P:\Programme\Anaconda\lib\site-packages\flask\app.py", line 1967, in finalize_request
    response = self.make_response(rv)
  File "P:\Programme\Anaconda\lib\site-packages\flask\app.py", line 2130, in make_response
    " {rv.__class__.__name__}.".format(rv=rv)
TypeError: The view function did not return a valid response. The return type must be a string, dict, tuple, Response instance, or WSGI callable, but it was a int.
